Workbook

Sheet Titre
B21: Sources :
B22: DATAGOUV – Fichier RNA_waldec arrêtée au 01/02/2025 ; Florès 2018-2019; Extraction DRFIP - Réalisation MATT - Décembre 2020
B23: (Rappel pour la version précédente : DATAGOUV – Fichier RNA_waldec arrêtée au 01/02/2023 ; Florès 2017-2018)
B25: Réalisation :
B26: Le Compas pour le compte de la Délégation régionale académique à la jeunesse, à l’engagement et aux sports des Pays de la Loire
B29: Compas : lecompas.fr

Sheet Démographie des asso
B2: Indicateurs-clés | C2: 44 | D2: 49 | E2: 53 | F2: 72 | G2: 85 | H2: Pays de la Loire | I2: Rappel PDL Version précédente (Données 01/02/2023) | J2: Rappel PDL Version précédente (Données 01/02/2022) | K2: Rappel PDL Version précédente (Données 01/02/2021) | L2: Rappel PDL Version précédente (Données 01/10/2020) | M2: Rappel PDL Version précédente (Données 01/02/2019) | N2: Source(s) | O2: Date(s) des données | P2: Observations
B3: Nombre d'associations actives - RNA_waldec | C3: 34543 | D3: 29066 | E3: 8328 | F3: 18500 | G3: 17881 | H3: =SUM(C3:G3) -> 108318 | I3: 103535 | J3: 100019 | K3: 96583 | L3: 95653 | M3: 88994 | N3: DATAGOUV – Fichier RNA_waldec | O3: 45689 | P3: (= total RNA - les dissoutes)
B4: Répartition par département du nbre d'associations actives - RNA_waldec (total ligne = 100%) | C4: =C3/$H$3 -> 0.3189036 | D4: =D3/$H$3 -> 0.26833952 | E4: =E3/$H$3 -> 0.076884728 | F4: =F3/$H$3 -> 0.1707934 | G4: =G3/$H$3 -> 0.16507875 | H4: =SUM(C4:G4) -> 1 | I4: 1 | J4: 1 | K4: 1 | L4: 1 | M4: 1 | N4: DATAGOUV – Fichier RNA_waldec | O4: 45689
B5: Evolution annuelle moyenne des associations actives sur une période de 5 ans (en %) | C5: 0.039066726 | D5: 0.018194961 | E5: 0.022938823 | F5: 0.019745944 | G5: 0.027688575 | H5: 0.026744959 | I5: 0.027012474 | J5: 0.027258246 | K5: 0.029819745 | L5: 0.032 | M5: 0.035283987 | N5: DATAGOUV – Fichier RNA_waldec | O5: 2019-2025
B6: Nombre d’associations actives pour 1000 habitants* | C6: 23.448297 | D6: 35.097464 | E6: 27.265852 | F6: 32.678065 | G6: 25.314897 | H6: 27.922652 | I6: 27.199806 | J6: 26.276113 | K6: 25.541443 | L6: 25.5 | M6: 23.932691 | N6: DATAGOUV – Fichier RNA_waldec *Insee RP 2022 | O6: 45689
B7: Nombre d'associations dissoutes signalées dans le RNA_waldec | C7: 6434 | D7: 3980 | E7: 1670 | F7: 2489 | G7: 2975 | H7: 17548 | I7: 15262 | J7: 13956 | K7: 12697 | L7: 12327 | M7: 10695 | N7: DATAGOUV – Fichier RNA_waldec | O7: 45689
B8: Part des associations dissoutes dont la durée de vie est de moins de 5 ans | C8: 0.35607709 | D8: 0.25351759 | E8: 0.4 | F8: 0.25271193 | G8: 0.26487395 | H8: 0.30687258 | I8: 0.30893723 | J8: 0.31427343 | K8: 0.31865448 | L8: 0.319 | M8: 0.31781206 | N8: DATAGOUV – Fichier RNA_waldec | O8: 45689
B9: Part des associations dissoutes dont la durée de vie est comprise entre 5 et 9 ans | C9: 0.21137706 | D9: 0.20376884 | E9: 0.11916168 | F9: 0.18119727 | G9: 0.20403361 | H9: 0.1953499 | I9: 0.19650111 | J9: 0.1957581 | K9: 0.19355601 | L9: 0.193 | M9: 0.19382889 | N9: DATAGOUV – Fichier RNA_waldec | O9: 45689
B10: Part des associations dissoutes dont la durée de vie est comprise entre 10 et 19 ans | C10: 0.21572894 | D10: 0.23693467 | E10: 0.17005988 | F10: 0.23664122 | G10: 0.23092437 | H10: 0.22173467 | I10: 0.22382388 | J10: 0.22277157 | K10: 0.22262486 | L10: 0.223 | M10: 0.22421692 | N10: DATAGOUV – Fichier RNA_waldec | O10: 45689
B11: Part des associations dissoutes dont la durée de vie est comprise entre 20 et 29 ans | C11: 0.10226919 | D11: 0.12788945 | E11: 0.10239521 | F11: 0.11932503 | G11: 0.11697479 | H11: 0.11300433 | I11: 0.11302582 | J11: 0.11242476 | K11: 0.11241531 | L11: 0.112 | M11: 0.11192146 | N11: DATAGOUV – Fichier RNA_waldec | O11: 45689
B12: Part des associations dissoutes dont la durée de vie est comprise entre 30 et 39 ans | C12: 0.057973267 | D12: 0.07160804 | E12: 0.07005988 | F12: 0.090799518 | G12: 0.075630252 | H12: 0.069865512 | I12: 0.068405189 | J12: 0.06692462 | K12: 0.06601544 | L12: 0.065 | M12: 0.064422627 | N12: DATAGOUV – Fichier RNA_waldec | O12: 45689
B13: Part des associations dissoutes dont la durée de vie est de 40 ans ou plus | C13: 0.056574448 | D13: 0.10628141 | E13: 0.13832335 | F13: 0.11932503 | G13: 0.10756303 | H13: 0.093173011 | I13: 0.089306775 | J13: 0.087847521 | K13: 0.08673389 | L13: 0.087 | M13: 0.087798036 | N13: DATAGOUV – Fichier RNA_waldec | O13: 45689
B14: Nombre de créations sur la dernière année connue | C14: 1747 | D14: 826 | E14: 283 | F14: 563 | G14: 721 | H14: 4140 | I14: 3834 | J14: 3495 | K14: 3143 | L14: 3986 | M14: 3892 | N14: DATAGOUV – Fichier RNA_waldec | O14: 2024 | P14: base de calcul : asso actives
B15: Part des créations parmi les associations de la dernière année entière connue (en %) | C15: =C14/C3 -> 0.050574646 | D15: =D14/D3 -> 0.028418083 | E15: =E14/E3 -> 0.033981748 | F15: =F14/F3 -> 0.030432432 | G15: =G14/G3 -> 0.04032213 | H15: =H14/H3 -> 0.038220794 | I15: 0.037030956 | J15: 0.034943361 | K15: 0.032541959 | L15: 0.041671458 | M15: 0.044 | N15: DATAGOUV – Fichier RNA_waldec | O15: 2024 | P15: base de calcul : asso actives
B16: Nombre d'associations récentes (moins de 5 ans d'existence) | C16: 7960 | D16: 3703 | E16: 1288 | F16: 2565 | G16: 3266 | H16: 18415 | I16: 18415 | J16: 18373 | K16: 18662 | L16: 21678 | M16: 19925 | N16: DATAGOUV – Fichier RNA_waldec | O16: 2020-2024 | P16: base de calcul : asso actives
B17: Part des associations récentes (moins de 5 ans d'existence) (en %) | C17: =C16/C3 -> 0.23043743 | D17: =D16/D3 -> 0.12739971 | E17: =E16/E3 -> 0.15465898 | F17: =F16/F3 -> 0.13864865 | G17: =G16/G3 -> 0.18265198 | H17: =H16/H3 -> 0.17000868 | I17: 0.17786256 | J17: 0.1836951 | K17: 0.19322241 | L17: 0.22663168 | M17: 0.20830502 | N17: DATAGOUV – Fichier RNA_waldec | O17: 2020-2024 | P17: base de calcul : asso actives
B18: Nbre moyen annuel de créations (sur les 5 dernières années disponibles) | C18: 1592 | D18: 740.6 | E18: 257.6 | F18: 513 | G18: 653.2 | H18: 3756.4 | I18: 3683 | J18: 3674.6 | K18: 3732.4 | L18: 3881.4 | M18: 3904.4 | N18: DATAGOUV – Fichier RNA_waldec | O18: 2020-2024 | P18: base de calcul : asso actives

Sheet Asso employeuses
B2: Indicateurs-clés | C2: 44 | D2: 49 | E2: 53 | F2: 72 | G2: 85 | H2: Pays de la Loire | I2: France métropolitaine | J2: Rappel PDL Version précédente | K2: Source(s) | L2: Date(s) des données | M2: Observations
B3: Nombre d'associations employeuses | C3: 4763 | D3: 2853 | E3: 989 | F3: 1536 | G3: 1472 | H3: =SUM(C3:G3) -> 11613 | I3: 172116 | J3: 12166 | K3: Florès 2019 | L3: 43800
B4: Evolution annuelle du nb d'associations employeuses - dernières années connues (en %) | C4: 0.037 | D4: 0.001 | E4: -0.001 | F4: 0.043 | G4: -0.312 | H4: +2,8% | I4: 0.024 | J4: 0.028 | K4: Florès 2019 | L4: déc-19 déc-18
B5: Répartition par département du nbre d'associations employeuses (total = 100%) | C5: 0.41 | D5: 0.25 | E5: 0.09 | F5: 0.13 | G5: 0.13 | H5: 1 | I5: - | J5: 1 | K5: Florès 2019 | L5: 43800
B6: Part des associations employeuses (en %) [parmi les associations actives du RNA_waldeck] | C6: =C3/'Démographie des asso'!C3 -> 0.13788611 | D6: =D3/'Démographie des asso'!D3 -> 0.098155921 | E6: =E3/'Démographie des asso'!E3 -> 0.118756 | F6: =F3/'Démographie des asso'!F3 -> 0.083027027 | G6: =G3/'Démographie des asso'!G3 -> 0.082322018 | H6: =H3/'Démographie des asso'!H3 -> 0.1072121 | I6: - | J6: 0.13 | K6: Florès 2019 ; RNA_waldec 2022
B7: Nombre de salariés en associations | C7: 55713 | D7: 35117 | E7: 10763 | F7: 16943 | G7: 23922 | H7: =SUM(C7:G7) -> 142458 | I7: 2029991 | J7: 141545 | K7: Florès 2019 | L7: 43800
B8: Evolution annuelle du nb de salariés en association - dernières années connues (en %) | C8: 0.039 | D8: 0.015 | E8: -0.014 | F8: 0.003 | G8: 0.017 | H8: 0.021 | I8: 0.024 | J8: 0.019 | K8: Florès 2019 | L8: déc-19 déc-18
B9: Répartition par département du nbre de salariés (total = 100%) | C9: 0.391 | D9: 0.247 | E9: 0.076 | F9: 0.119 | G9: 0.168 | H9: 1 | I9: - | J9: 1 | K9: Florès 2019 | L9: 43800
B10: Nombre moyen de salariés par association | C10: =C7/C3 -> 11.69704 | D10: =D7/D3 -> 12.308798 | E10: =E7/E3 -> 10.88271 | F10: =F7/F3 -> 11.030599 | G10: =G7/G3 -> 16.251359 | H10: =H7/H3 -> 12.267114 | I10: =I7/I3 -> 11.794319 | J10: 11.6 | K10: Florès 2019 | L10: 43800
B11: Part des salariés en association parmi l'ensemble des salariés (en %) | C11: 0.0954 | D11: 0.1191 | E11: 0.0968 | F11: 0.0882 | G11: 0.1005 | H11: 0.1 | I11: 0.122 | J11: 0.103 | K11: Florès 2019 | L11: 43800
B12: Nombre d'ETP en associations | C12: 42595.98 | D12: 26385.73 | E12: 8301.21 | F12: 12787.91 | G12: 17822.73 | H12: =SUM(C12:G12) -> 107893.56 | I12: 1541914.3 | J12: 107077 | K12: Florès 2019 | L12: 43800
B13: Répartition par département du nbre d'ETP (total = 100%) | C13: 0.395 | D13: 0.245 | E13: 0.077 | F13: 0.119 | G13: 0.165 | H13: 1 | I13: - | J13: 1 | K13: Florès 2019 | L13: 43800
B14: Nombre moyen d'ETP par association | C14: =C12/C3 -> 8.9430989 | D14: =D12/D3 -> 9.2484157 | E14: =E12/E3 -> 8.3935389 | F14: =F12/F3 -> 8.3254622 | G14: =G12/G3 -> 12.107833 | H14: =H12/H3 -> 9.2907569 | I14: =I12/I3 -> 8.9585761 | J14: 8.8 | K14: Florès 2019 | L14: 43800
B15: Rapport entre le nombre de salariés et le nombre d'ETP | C15: =C7/C12 -> 1.3079403 | D15: =D7/D12 -> 1.3309088 | E15: =E7/E12 -> 1.296558 | F15: =F7/F12 -> 1.3249233 | G15: =G7/G12 -> 1.3422186 | H15: =H7/H12 -> 1.3203568 | I15: =I7/I12 -> 1.3165395 | J15: 1.32 | K15: Florès 2019 | L15: 43800
B16: Poids des rémunérations des associations dans l'ensemble des rémunérations (en %) | C16: 0.069 | D16: 0.094 | E16: 0.078 | F16: 0.067 | G16: 0.077 | H16: 7,6 % | I16: 0.059 | J16: 0.076 | K16: Florès 2019 | L16: 43800

Sheet Compléments-Objet
B2: Indicateurs-clés | C2: 44 | D2: 49 | E2: 53 | F2: 72 | G2: 85 | H2: Pays de la Loire | I2: Rappel PDL Version précédente (Données 01/02/2023) | J2: Rappel PDL Version précédente (Données 01/02/2022) | K2: Rappel PDL Version précédente (Données 01/02/2021) | L2: Rappel PDL Version précédente (Données 01/10/2020) | M2: Rappel PDL Version précédente (Données 01/02/2019) | N2: Source(s) | O2: Date(s) des données | P2: Observations
B3: Nombre total d'associations actives | C3: 34543 | D3: 29066 | E3: 8328 | F3: 18500 | G3: 17881 | H3: 108318 | I3: 103535 | J3: 100019 | K3: 96583 | L3: 95653 | M3: ='Démographie des asso'!M3 -> 88994 | N3: DATAGOUV – Fichier RNA_waldec | O3: 45689
B4: Loisirs et Vie sociale | C4: 7786 | D4: 6196 | E4: 1904 | F4: 4488 | G4: 3200 | H4: 23574 | I4: 22443 | J4: 21762 | K4: 21060 | L4: 20863 | M4: 19308 | N4: DATAGOUV – Fichier RNA_waldec | O4: 45689
B5: Part parmi l'ensemble des associations du département | C5: =C4/C3 -> 0.22540023 | D5: =D4/D3 -> 0.21317003 | E5: =E4/E3 -> 0.22862632 | F5: =F4/F3 -> 0.24259459 | G5: =G4/G3 -> 0.17896091 | H5: =H4/H3 -> 0.21763696 | I5: 0.21676728 | J5: 0.21757866 | K5: 0.2180508 | L5: 0.2181113 | M5: 0.22 | N5: DATAGOUV – Fichier RNA_waldec | O5: 45689 | P5: (total colonne = 100%)
B6: Evolution annuelle moyenne sur une période de 5 ans (en %) | C6: 0.042282923 | D6: 0.016626735 | E6: 0.020028239 | F6: 0.013235132 | G6: 0.028335972 | H6: 0.025866185 | I6: 0.02656309 | J6: 0.026292375 | K6: 0.02940205 | L6: 0.031 | M6: 0.034839187 | N6: DATAGOUV – Fichier RNA_waldec | O6: 2020-2025
B7: Part des créations parmi les associations de la dernière année entière connue (en %) | C7: 0.058717254 | D7: 0.030881164 | E7: 0.039432177 | F7: 0.025011166 | G7: 0.042753851 | H7: 0.041242818 | I7: 0.035714286 | J7: 0.032192696 | K7: 0.032908503 | L7: 0.043 | M7: 0.040825806 | N7: DATAGOUV – Fichier RNA_waldec | O7: 2024
B8: Sport | C8: 6415 | D8: 6000 | E8: 2054 | F8: 4612 | G8: 4309 | H8: 23390 | I8: 22177 | J8: 21406 | K8: 20813 | L8: 20632 | M8: 19143 | N8: DATAGOUV – Fichier RNA_waldec | O8: 45689
B9: Part parmi l'ensemble des associations du département | C9: =C8/C3 -> 0.18571056 | D9: =D8/D3 -> 0.20642675 | E9: =E8/E3 -> 0.24663785 | F9: =F8/F3 -> 0.2492973 | G9: =G8/G3 -> 0.24098205 | H9: =H8/H3 -> 0.21593826 | I9: 0.2141981 | J9: 0.21401934 | K9: 0.21549341 | L9: 0.21569632 | M9: 0.22 | N9: DATAGOUV – Fichier RNA_waldec | O9: 45689 | P9: (total colonne = 100%)
B10: Evolution annuelle moyenne sur une période de 5 ans (en %) | C10: 0.030850732 | D10: 0.017046451 | E10: 0.025668687 | F10: 0.023091251 | G10: 0.029906 | H10: 0.025045932 | I10: 0.026191907 | J10: 0.02485172 | K10: 0.026691059 | L10: 0.029 | M10: 0.032091995 | N10: DATAGOUV – Fichier RNA_waldec | O10: 2020-2025
B11: Part des créations parmi les associations de la dernière année entière connue (en %) | C11: 0.04365514 | D11: 0.019859813 | E11: 0.036567528 | F11: 0.030448021 | G11: 0.040764034 | H11: 0.033783494 | I11: 0.033331826 | J11: 0.028319993 | K11: 0.027477022 | L11: 0.033 | M11: 0.038447474 | N11: DATAGOUV – Fichier RNA_waldec | O11: 2024
B12: Culture | C12: 7978 | D12: 4955 | E12: 999 | F12: 2776 | G12: 2855 | H12: 19563 | I12: 18623 | J12: 17842 | K12: 16947 | L12: 16789 | M12: 15607 | N12: DATAGOUV – Fichier RNA_waldec | O12: 45689
B13: Part parmi l'ensemble des associations du département | C13: =C12/C3 -> 0.23095852 | D13: =D12/D3 -> 0.17047409 | E13: =E12/E3 -> 0.11995677 | F13: =F12/F3 -> 0.15005405 | G13: =G12/G3 -> 0.15966669 | H13: =H12/H3 -> 0.1806071 | I13: 0.17987154 | J13: 0.17838611 | K13: 0.17546566 | L13: 0.17551985 | M13: 0.18 | N13: DATAGOUV – Fichier RNA_waldec | O13: 45689 | P13: (total colonne = 100%)
B14: Evolution annuelle moyenne sur une période de 5 ans (en %) | C14: 0.043186388 | D14: 0.026608768 | E14: 0.029784601 | F14: 0.025485583 | G14: 0.038517074 | H14: 0.034902079 | I14: 0.040275751 | J14: 0.040422494 | K14: 0.044481634 | L14: 0.049 | M14: 0.053237143 | N14: DATAGOUV – Fichier RNA_waldec | O14: 2020-2025
B15: Part des créations parmi les associations de la dernière année entière connue (en %) | C15: 0.057660833 | D15: 0.045730473 | E15: 0.03006012 | F15: 0.039350181 | G15: 0.055555556 | H15: 0.050315433 | I15: 0.045158161 | J15: 0.044054844 | K15: 0.040101733 | L15: 0.058 | M15: 0.059456689 | N15: DATAGOUV – Fichier RNA_waldec | O15: 2024
B16: Santé et Action sociale | C16: 4312 | D16: 3823 | E16: 1124 | F16: 1934 | G16: 1929 | H16: 13122 | I16: 12465 | J16: 11882 | K16: 11374 | L16: 11228 | M16: 10494 | N16: DATAGOUV – Fichier RNA_waldec | O16: 45689
B17: Part parmi l'ensemble des associations du département | C17: =C16/C3 -> 0.12482992 | D17: =D16/D3 -> 0.13152825 | E17: =E16/E3 -> 0.13496638 | F17: =F16/F3 -> 0.10454054 | G17: =G16/G3 -> 0.10787987 | H17: =H16/H3 -> 0.1211433 | I17: 0.12039407 | J17: 0.11879743 | K17: 0.117764 | L17: 0.11738262 | M17: 0.12 | N17: DATAGOUV – Fichier RNA_waldec | O17: 45689 | P17: (total colonne = 100%)
B18: Evolution annuelle moyenne sur une période de 5 ans (en %) | C18: 0.044374136 | D18: 0.021840541 | E18: 0.039005283 | F18: 0.025062954 | G18: 0.044789661 | H18: 0.034172747 | I18: 0.037552108 | J18: 0.035990199 | K18: 0.03611915 | L18: 0.038 | M18: 0.03887343 | N18: DATAGOUV – Fichier RNA_waldec | O18: 2020-2025
B19: Part des créations parmi les associations de la dernière année entière connue (en %) | C19: 0.044459963 | D19: 0.034111782 | E19: 0.042001787 | F19: 0.03621314 | G19: 0.066528067 | H19: 0.043262249 | I19: 0.05116204 | J19: 0.048846446 | K19: 0.038010407 | L19: 0.052 | M19: 0.055269678 | N19: DATAGOUV – Fichier RNA_waldec | O19: 2024
B20: Education et Formation | C20: 2893 | D20: 2822 | E20: 816 | F20: 1168 | G20: 1153 | H20: 8852 | I20: 8525 | J20: 8343 | K20: 8213 | L20: 8153 | M20: 7729 | N20: DATAGOUV – Fichier RNA_waldec | O20: 45689
B21: Part parmi l'ensemble des associations du département | C21: =C20/C3 -> 0.083750688 | D21: =D20/D3 -> 0.097089383 | E21: =E20/E3 -> 0.097982709 | F21: =F20/F3 -> 0.063135135 | G21: =G20/G3 -> 0.064481852 | H21: =H20/H3 -> 0.081722336 | I21: 0.082339306 | J21: 0.083414151 | K21: 0.085035669 | L21: 0.085235173 | M21: 0.09 | N21: DATAGOUV – Fichier RNA_waldec | O21: 45689 | P21: (total colonne = 100%)
B22: Evolution annuelle moyenne sur une période de 5 ans (en %) | C22: 0.026670146 | D22: 0.0088976017 | E22: 0.0017323908 | F22: 0.022549745 | G22: 0.011167055 | H22: 0.015869489 | I22: 0.016791094 | J22: 0.014798824 | K22: 0.016731159 | L22: 0.018 | M22: 0.017058462 | N22: DATAGOUV – Fichier RNA_waldec | O22: 2020-2025
B23: Part des créations parmi les associations de la dernière année entière connue (en %) | C23: 0.053744799 | D23: 0.012765957 | E23: 0.013480392 | F23: 0.036051502 | G23: 0.015611448 | H23: 0.029644716 | I23: 0.026566357 | J23: 0.022224892 | K23: 0.020955166 | L23: 0.032 | M23: 0.030534351 | N23: DATAGOUV – Fichier RNA_waldec | O23: 2024
B24: Economie et Développement local | C24: 2152 | D24: 2311 | E24: 497 | F24: 1362 | G24: 1021 | H24: 7343 | I24: 7187 | J24: 7004 | K24: 6833 | L24: 6785 | M24: 6261 | N24: DATAGOUV – Fichier RNA_waldec | O24: 45689
B25: Part parmi l'ensemble des associations du département | C25: =C24/C3 -> 0.062299163 | D25: =D24/D3 -> 0.079508704 | E25: =E24/E3 -> 0.059678194 | F25: =F24/F3 -> 0.073621622 | G25: =G24/G3 -> 0.057099715 | H25: =H24/H3 -> 0.067791134 | I25: 0.069416139 | J25: 0.070026695 | K25: 0.07074744 | L25: 0.070933478 | M25: 0.065455344 | N25: DATAGOUV – Fichier RNA_waldec | O25: 45689 | P25: (total colonne = 100%)
B26: Evolution annuelle moyenne sur une période de 5 ans (en %) | C26: 0.031638128 | D26: 0.011953728 | E26: 0.013928169 | F26: 0.0073939487 | G26: 0.019212893 | H26: 0.01770913 | I26: 0.021484931 | J26: 0.018850473 | K26: 0.021068498 | L26: 0.021 | M26: 0.023624681 | N26: DATAGOUV – Fichier RNA_waldec | O26: 2020-2025
B27: Part des créations parmi les associations de la dernière année entière connue (en %) | C27: 0.04011194 | D27: 0.022501082 | E27: 0.024242424 | F27: 0.022727273 | G27: 0.037364798 | H27: 0.029873141 | I27: 0.032352531 | J27: 0.030758226 | K27: 0.031666911 | L27: 0.043124102 | M27: 0.043124102 | N27: DATAGOUV – Fichier RNA_waldec | O27: 2024
B28: Environnement et Patrimoine | C28: 1611 | D28: 1522 | E28: 498 | F28: 1018 | G28: 893 | H28: 5542 | I28: 5218 | J28: 4996 | K28: 4729 | L28: 4642 | M28: 4107 | N28: DATAGOUV – Fichier RNA_waldec | O28: 45689
B29: Part parmi l'ensemble des associations du département | C29: =C28/C3 -> 0.046637524 | D29: =D28/D3 -> 0.052363586 | E29: =E28/E3 -> 0.059798271 | F29: =F28/F3 -> 0.055027027 | G29: =G28/G3 -> 0.049941278 | H29: =H28/H3 -> 0.051164165 | I29: 0.050398416 | J29: 0.049950509 | K29: 0.048963068 | L29: 0.048529581 | M29: 0.05 | N29: DATAGOUV – Fichier RNA_waldec | O29: 45689 | P29: (total colonne = 100%)
B30: Evolution annuelle moyenne sur une période de 5 ans (en %) | C30: 0.054440317 | D30: 0.027647656 | E30: 0.034512392 | F30: 0.034917346 | G30: 0.054685326 | H30: 0.041253414 | I30: 0.045101758 | J30: 0.042361493 | K30: 0.042816571 | L30: 0.038 | M30: 0.039673676 | N30: DATAGOUV – Fichier RNA_waldec | O30: 2020-2025
B31: Part des créations parmi les associations de la dernière année entière connue (en %) | C31: 0.046758105 | D31: 0.034868421 | E31: 0.050301811 | F31: 0.026548673 | G31: 0.046538025 | H31: 0.040043486 | I31: 0.046251686 | J31: 0.053097345 | K31: 0.057124655 | L31: 0.055 | M31: 0.053323594 | N31: DATAGOUV – Fichier RNA_waldec | O31: 2024
B32: Autres et Divers | C32: 1394 | D32: 1428 | E32: 436 | F32: 1130 | G32: 2511 | H32: 6899 | I32: 6864 | J32: 6750 | K32: 6614 | L32: 6528 | M32: 6250 | N32: DATAGOUV – Fichier RNA_waldec | O32: 45689
B33: Part parmi l'ensemble des associations du département | C33: =C32/C3 -> 0.040355499 | D33: =D32/D3 -> 0.049129567 | E33: =E32/E3 -> 0.052353506 | F33: =F32/F3 -> 0.061081081 | G33: =G32/G3 -> 0.14042839 | H33: =H32/H3 -> 0.063692092 | I33: 0.066296421 | J33: 0.067487177 | K33: 0.06847996 | L33: 0.068246683 | M33: 0.065340345 | N33: DATAGOUV – Fichier RNA_waldec | O33: 45689 | P33: (total colonne = 100%)
B34: Evolution annuelle moyenne sur une période de 5 ans (en %) | C34: 0.019919046 | D34: 0.011549634 | E34: 0.010472727 | F34: 0.015644393 | G34: 0.0028965621 | H34: 0.01054227 | I34: 0.012914822 | J34: 0.013215537 | K34: 0.01258072 | L34: 0.017 | M34: 0.01969826 | N34: DATAGOUV – Fichier RNA_waldec | O34: 2020-2025
B35: Part des créations parmi les associations de la dernière année entière connue (en %) | C35: 0.034482759 | D35: 0.013305322 | E35: 0.018390805 | F35: 0.028343667 | G35: 0.010761259 | H35: 0.019440012 | I35: 0.018661612 | J35: 0.024477081 | K35: 0.017348958 | L35: 0.024 | M35: 0.01792 | N35: DATAGOUV – Fichier RNA_waldec | O35: 2024

Sheet Compléments-Cat Aires Urbaines
B2: Indicateurs-clés | C2: 44 | D2: 49 | E2: 53 | F2: 72 | G2: 85 | H2: Pays de la Loire | I2: Rappel PDL Version précédente (Données 01/02/2023) | J2: Rappel PDL Version précédente (Données 01/02/2022) | K2: Rappel PDL Version précédente (Données 01/02/2021) | L2: Rappel PDL Version précédente (Données 01/10/2020) | M2: Rappel PDL Version précédente (Données 01/02/2019) | N2: Source(s) | O2: Date(s) des données | P2: Observations
B3: Nombre total d'associations actives | C3: 34543 | D3: 29066 | E3: 8328 | F3: 18500 | G3: 17881 | H3: 108318 | I3: 103535 | J3: 100019 | K3: ='Compléments-Objet'!K3 -> 96583 | L3: ='Compléments-Objet'!L3 -> 95653 | M3: ='Démographie des asso'!M3 -> 88994 | N3: DATAGOUV – Fichier RNA_waldec | O3: 45689
B4: Selon la catégorie dans le zonage en aires urbaines (Insee) (total colonne = 100%)
B5: Associations d'une commune appartenant à un grand pôle (10 000 emplois ou plus) | C5: 21707 | D5: 13800 | E5: 2336 | F5: 8596 | G5: 4909 | H5: 51348 | I5: 49194 | J5: 47591 | K5: 45769 | L5: 45336 | M5: 42368 | N5: DATAGOUV – Fichier RNA_waldec | O5: 45689 | P5: Les définitions des notions utilisées dans ce fichier sont accessibles dans la rubrique "Définitions, méthodes et qualité" du site internet de l'Insee : https://www.insee.fr/fr/metadonnees/definitions
B6: Part parmi l'ensemble des associations du département | C6: =C5/C3 -> 0.62840518 | D6: =D5/D3 -> 0.47478153 | E6: =E5/E3 -> 0.28049952 | F6: =F5/F3 -> 0.46464865 | G6: =G5/G3 -> 0.27453722 | H6: =H5/H3 -> 0.47404863 | I6: 0.47514367 | J6: 0.47581959 | K6: 0.45760306 | L6: 0.46939938 | M6: 0.48 | N6: DATAGOUV – Fichier RNA_waldec | O6: 45689
B7: Nombre d'associations pour 1000 habitants* | C7: 25.137313 | D7: 42.664358 | E7: 28.176489 | F7: 35.317948 | G7: 29.228241 | H7: 30.541725 | I7: 29.904549 | J7: 29.207003 | K7: 28.088826 | L7: 28.1 | M7: 26.5 | N7: Fichier RNA_waldec *Insee RP 2019 | O7: 45689
B8: Associations d'une commune appartenant à la couronne d'un grand pôle | C8: 8072 | D8: 8461 | E8: 1582 | F8: 4678 | G8: 2355 | H8: 25148 | I8: 23931 | J8: 23153 | K8: 22399 | L8: 22164 | M8: 20605 | N8: DATAGOUV – Fichier RNA_waldec | O8: 45689
B9: Part parmi l'ensemble des associations du département | C9: =C8/C3 -> 0.23367976 | D9: =D8/D3 -> 0.29109613 | E9: =E8/E3 -> 0.18996158 | F9: =F8/F3 -> 0.25286486 | G9: =G8/G3 -> 0.13170404 | H9: =H8/H3 -> 0.23216825 | I9: 0.23113923 | J9: 0.23148602 | K9: 0.22394745 | L9: 0.22948138 | M9: 0.23 | N9: DATAGOUV – Fichier RNA_waldec | O9: 45689
B10: Nombre d'associations pour 1000 habitants* | C10: 20.453411 | D10: 31.165282 | E10: 21.925023 | F10: 27.329396 | G10: 23.636272 | H10: 24.921168 | I10: 23.770832 | J10: 23.156002 | K10: 22.403839 | L10: 22.3 | M10: 20.8 | N10: Fichier RNA_waldec *Insee RP 2019 | O10: 45689
B11: Associations d'une commune multipolarisée des grandes aires urbaines | C11: 1419 | D11: 698 | E11: 369 | F11: 1308 | G11: 1923 | H11: 5717 | I11: 5393 | J11: 5173 | K11: 5040 | L11: 4997 | M11: 4750 | N11: DATAGOUV – Fichier RNA_waldec | O11: 45689
B12: Part parmi l'ensemble des associations du département | C12: =C11/C3 -> 0.041079235 | D12: =D11/D3 -> 0.024014312 | E12: =E11/E3 -> 0.044308357 | F12: =F11/F3 -> 0.070702703 | G12: =G11/G3 -> 0.10754432 | H12: =H11/H3 -> 0.052779778 | I12: 0.052088666 | J12: 0.051720173 | K12: 0.050390426 | L12: 0.051737883 | M12: 0.05 | N12: DATAGOUV – Fichier RNA_waldec | O12: 45689
B13: Nombre d'associations pour 1000 habitants* | C13: 22.856499 | D13: 30.238704 | E13: 24.775077 | F13: 29.899877 | G13: 21.824496 | H13: 24.650954 | I13: 23.844474 | J13: 22.973033 | K13: 22.391044 | L13: 22.3 | M13: 21.2 | N13: Fichier RNA_waldec *Insee RP 2019 | O13: 45689
B14: Associations d'une commune appartenant à un moyen pôle (5 000 à moins de 10 000 emplois) | C14: 1384 | D14: 452 | E14: 694 | F14: 509 | G14: 1398 | H14: 4437 | I14: 4227 | J14: 4029 | K14: 3881 | L14: 3846 | M14: 3701 | N14: DATAGOUV – Fichier RNA_waldec | O14: 45689
B15: Part parmi l'ensemble des associations du département | C15: =C14/C3 -> 0.040066005 | D15: =D14/D3 -> 0.015550815 | E15: =E14/E3 -> 0.083333333 | F15: =F14/F3 -> 0.027513514 | G15: =G14/G3 -> 0.078183547 | H15: =H14/H3 -> 0.040962721 | I15: 0.040826774 | J15: 0.040282346 | K15: 0.038802628 | L15: 0.039820672 | M15: 0.04 | N15: DATAGOUV – Fichier RNA_waldec | O15: 45689
B16: Nombre d'associations pour 1000 habitants* | C16: 22.318981 | D16: 25.657036 | E16: 27.850235 | F16: 33.751078 | G16: 23.928523 | H16: 24.919826 | I16: 24.594027 | J16: 23.593828 | K16: 22.72714 | L16: 22.7 | M16: 23 | N16: Fichier RNA_waldec *Insee RP 2019 | O16: 45689
B17: Associations d'une commune appartenant à la couronne d'un moyen pôle | C17: 227 | D17: 0 | E17: 415 | F17: 65 | G17: 107 | H17: 814 | I17: 782 | J17: 751 | K17: 724 | L17: 718 | M17: 702 | N17: DATAGOUV – Fichier RNA_waldec | O17: 45689
B18: Part parmi l'ensemble des associations du département | C18: =C17/C3 -> 0.0065715196 | D18: 0 | E18: =E17/E3 -> 0.049831892 | F18: =F17/F3 -> 0.0035135135 | G18: =G17/G3 -> 0.0059840054 | H18: =H17/H3 -> 0.0075149098 | I18: 0.0075530014 | J18: 0.0075085734 | K18: 0.0072386247 | L18: 0.0074340205 | M18: 0.01 | N18: DATAGOUV – Fichier RNA_waldec | O18: 45689
B19: Nombre d'associations pour 1000 habitants* | C19: 18.380567 | D19: 0 | E19: 30.795488 | F19: 32.226078 | G19: 17.848207 | H19: 24.055795 | I19: 23.044734 | J19: 22.075899 | K19: 21.282225 | L19: 21.1 | M19: 19.5 | N19: Fichier RNA_waldec *Insee RP 2019 | O19: 45689
B20: Associations d'une commune appartenant à un petit pôle (de 1 500 à moins de 5 000 emplois) | C20: 726 | D20: 3662 | E20: 529 | F20: 1081 | G20: 2161 | H20: 8159 | I20: 7824 | J20: 7550 | K20: 7401 | L20: 7304 | M20: 6352 | N20: DATAGOUV – Fichier RNA_waldec | O20: 45689
B21: Part parmi l'ensemble des associations du département | C21: =C20/C3 -> 0.021017283 | D21: =D20/D3 -> 0.12598913 | E21: =E20/E3 -> 0.063520653 | F21: =F20/F3 -> 0.058432432 | G21: =G20/G3 -> 0.12085454 | H21: =H20/H3 -> 0.075324507 | I21: 0.075568648 | J21: 0.075485658 | K21: 0.073995941 | L21: 0.075624075 | M21: 0.07 | N21: DATAGOUV – Fichier RNA_waldec | O21: 45689
B22: Nombre d'associations pour 1000 habitants* | C22: 23.217884 | D22: 32.25153 | E22: 29.607657 | F22: 40.00296 | G22: 28.030716 | H22: 30.581189 | I22: 29.470481 | J22: 28.413902 | K22: 27.853151 | L22: 27.4 | M22: 24 | N22: Fichier RNA_waldec *Insee RP 2019 | O22: 45689
B23: Associations d'une commune appartenant à la couronne d'un petit pôle | C23: 0 | D23: 0 | E23: 46 | F23: 39 | G23: 0 | H23: 85 | I23: 83 | J23: 86 | K23: 82 | L23: 82 | M23: 81 | N23: DATAGOUV – Fichier RNA_waldec | O23: 45689
B24: Part parmi l'ensemble des associations du département | C24: 0 | D24: 0 | E24: =E23/E3 -> 0.0055235351 | F24: =F23/F3 -> 0.0021081081 | G24: 0 | H24: =H23/H3 -> 0.00078472645 | I24: 0.00080166127 | J24: 0.00085983663 | K24: 0.00081984423 | L24: 0.0008490107 | M24: 0.001 | N24: DATAGOUV – Fichier RNA_waldec | O24: 45689
B25: Nombre d'associations pour 1000 habitants* | C25: 0 | D25: 0 | E25: 30.483764 | F25: 25.540275 | G25: 0 | H25: 27.997365 | I25: 27.383702 | J25: 28.308097 | K25: 26.991442 | L25: 26.9 | M25: 26.5 | N25: Fichier RNA_waldec *Insee RP 2019 | O25: 45689
B26: Associations d'une autre commune multipolarisée | C26: 1008 | D26: 1530 | E26: 1256 | F26: 1707 | G26: 3990 | H26: 9491 | I26: 9090 | J26: 8745 | K26: 8419 | L26: 8349 | M26: 7788 | N26: DATAGOUV – Fichier RNA_waldec | O26: 45689
B27: Part parmi l'ensemble des associations du département | C27: =C26/C3 -> 0.029181021 | D27: =D26/D3 -> 0.052638822 | E27: =E26/E3 -> 0.15081652 | F27: =F26/F3 -> 0.09227027 | G27: =G26/G3 -> 0.22314188 | H27: =H26/H3 -> 0.087621633 | I27: 0.087796397 | J27: 0.087433388 | K27: 0.084174007 | L27: 0.086443784 | M27: 0.09 | N27: DATAGOUV – Fichier RNA_waldec | O27: 45689
B28: Nombre d'associations pour 1000 habitants* | C28: 21.331527 | D28: 29.94598 | E28: 30.127129 | F28: 34.671866 | G28: 24.442089 | H28: 26.923906 | I28: 25.890207 | J28: 24.969805 | K28: 24.038969 | L28: 23.9 | M28: 21.9 | N28: Fichier RNA_waldec *Insee RP 2019 | O28: 45689
B29: Associations d'une commune isolée hors influence des pôles | C29: 0 | D29: 463 | E29: 1101 | F29: 517 | G29: 1038 | H29: 3119 | I29: 3011 | J29: 2941 | K29: 2862 | L29: 2851 | M29: 2642 | N29: DATAGOUV – Fichier RNA_waldec | O29: 45689
B30: Part parmi l'ensemble des associations du département | C30: 0 | D30: =D29/D3 -> 0.015929264 | E30: =E29/E3 -> 0.13220461 | F30: =F29/F3 -> 0.027945946 | G30: =G29/G3 -> 0.058050445 | H30: =H29/H3 -> 0.028794845 | I30: 0.029081953 | J30: 0.029404413 | K30: 0.028614563 | L30: 0.029518652 | M30: 0.03 | N30: DATAGOUV – Fichier RNA_waldec | O30: 45689
B31: Nombre d'associations pour 1000 habitants* | C31: 0 | D31: 42.492658 | E31: 30.565503 | F31: 39.947458 | G31: 23.262068 | H31: 29.852318 | I31: 29.206072 | J31: 28.50552 | K31: 27.739816 | L31: 27.6 | M31: 25.5 | N31: Fichier RNA_waldec *Insee RP 2019 | O31: 45689
B32: Selon le classement en Zone de Revitalisation Rurale (ZRR)
B33: Associations d'une commune classée en ZRR | C33: 1395 | D33: 4170 | E33: 3512 | F33: 5162 | G33: 2180 | H33: 16419 | I33: 15846 | J33: 15383 | K33: 14932 | L33: 14849 | M33: 14162 | N33: DATAGOUV – Fichier RNA_waldec | O33: 45689
B34: Répartition par département du nbre d'associations en ZRR (total ligne = 100%) | C34: =C33/$H$33 -> 0.084962543 | D34: =D33/$H$33 -> 0.25397405 | E34: =E33/$H$33 -> 0.21389853 | F34: =F33/$H$33 -> 0.31439186 | G34: =G33/$H$33 -> 0.13277301 | H34: =H33/$H$33 -> 1 | I34: - | J34: - | K34: - | L34: - | M34: - | N34: DATAGOUV – Fichier RNA_waldec | O34: 45689
B35: Part parmi l'ensemble des associations du département | C35: =C33/C3 -> 0.040384448 | D35: =D33/D3 -> 0.14346659 | E35: =E33/E3 -> 0.42170989 | F35: =F33/F3 -> 0.27902703 | G35: =G33/G3 -> 0.12191712 | H35: =H33/H3 -> 0.15158145 | I35: 0.15304969 | J35: 0.15380078 | K35: 0.14929163 | L35: 0.15374341 | M35: 0.16 | N35: DATAGOUV – Fichier RNA_waldec | O35: 45689
B36: Nombre d'associations pour 1000 habitants* | C36: 22.830303 | D36: 31.151252 | E36: 28.483143 | F36: 34.16959 | G36: 24.929956 | H36: 29.4891 | I36: 28.319185 | J36: 27.491734 | K36: 26.621549 | L36: 26.4 | M36: 25.1 | N36: Fichier RNA_waldec *Insee RP 2019 | O36: 45689

Sheet Subventionnement Etat
A1: Recapitulatif des subventions versées aux associations par BOP et par années
B2: 2019 | C2: 2018 | D2: 2017 | E2: 2016 | F2: 2015
A3: BOP DRDJSCS | B3: 88229323 | C3: 84177572 | D3: 83976366 | E3: 81154860 | F3: 60051378
A4: BOP DREAL | B4: 3012730 | C4: 3137753 | D4: 2860325.9 | E4: 3093922.2 | F4: 2768625.8
A5: BOP DIRECCTE | B5: 23320293 | C5: 23642881 | D5: 23145839 | E5: 20145864 | F5: 17901291
A6: BOP DRAC | B6: 16527380 | C6: 14032780 | D6: 13604472 | E6: 12915628 | F6: 11778937
A7: BOP PREFET REGION | B7: 33922146 | C7: 12019226 | D7: 9309129 | E7: 13839632 | F7: 18668430
A8: BOP PREFET 44 | B8: 2800672 | C8: 2542881 | D8: 261236
A9: BOP PREFET 49 | B9: 2416633 | C9: 5109815 | D9: 5643279
A10: BOP PREFET 53 | B10: 772787 | C10: 2705549.5 | D10: 2061669.6
A11: BOP PREFET 72 | B11: 1479605 | C11: 6917409 | D11: 5754619.4
A12: BOP PREFET 85 | B12: 916776 | C12: 4266875.9 | D12: 3835095
A13: BOP RECTORAT | B13: 270790 | C13: 570547 | D13: 131437
A14: BOP DRAAF 44 | B14: 1301842.1 | C14: 1340850.3 | D14: 17458
A15: Total général | B15: 1.7497098e+08 | C15: 1.6046414e+08 | D15: 1.5060093e+08 | E15: 1.3114991e+08 | F15: 1.1116866e+08
A16: Source : Extraction DRFIP - Réalisation MATT - Décembre 2020
A18: Détail des subventions versées aux associations par BOP et par années
B19: 2019 | C19: 2018 | D19: 2017 | E19: 2016 | F19: 2015
A20: BOP DRDJSCS + DDCS | B20: 88229323 | C20: 84177572 | D20: 83976366 | E20: 81154860 | F20: 60051378
A21: dont DRDJSCS | B21: 3794668.4 | C21: 3681227.7 | D21: 2131737.9
A22: dont BOP DDCS 44 | B22: 33206052 | C22: 37757489 | D22: 31810271
A23: dont BOP DDCS 49 | B23: 18339537 | C23: 12685917 | D23: 17813161
A24: dont BOP DDCSPP 53 | B24: 7786421.9 | C24: 5412027 | D24: 7466992.2
A25: dont BOP DDCS 72 | B25: 13260085 | C25: 14319395 | D25: 13334317
A26: dont BOP DDCS 85 | B26: 11842558 | C26: 10321516 | D26: 11419887
A27: BOP DREAL + DDT | B27: 3012730 | C27: 3137753 | D27: 2860325.9 | E27: 3093922.2 | F27: 2768625.8
A28: dont BOP DREAL | B28: 2341292.5 | C28: 2083785.8 | D28: 2058646
A29: dont BOP DDTM 44 | B29: 335469 | C29: 498921.7 | D29: 388036
A30: dont BOP DDT 49 | B30: 152818.38 | C30: 112512.62 | D30: 239016.99
A31: dont BOP DDT 53 | B31: 14280 | C31: 106400 | D31: 56400
A32: dont BOP DDT 72 | B32: 22552.16 | C32: 60150 | D32: 27600
A33: dont BOP DDTM 85 | B33: 146317.89 | C33: 275982.88 | D33: 90626.88
A34: BOP DIRECCTE | B34: 23320293 | C34: 23642881 | D34: 23145839 | E34: 20145864 | F34: 17901291
A35: BOP DRAC | B35: 16527380 | C35: 14032780 | D35: 13604472 | E35: 12915628 | F35: 11778937
A36: BOP PREFET REGION | B36: 33922146 | C36: 12019226 | D36: 9309129 | E36: 13839632 | F36: 18668430
A37: dont BOP Politique de la ville | B37: 322200 | C37: 433720
A38: BOP PREFET 44 | B38: 2800672 | C38: 2542881 | D38: 261236
A39: dont BOP Politique de la ville | B39: 1918426 | C39: 1619431
A40: BOP PREFET 49 | B40: 2416633 | C40: 5109815 | D40: 5643279
A41: dont BOP Politique de la ville | B41: 1140591 | C41: 1138807
...

Sheet Ann-1 - Asso dissoutes x Objet
B1: Année de la dissolution | J1: Année de la dissolution
B2: 2024 | C2: Objet Dataasso | D2: 44 | E2: 49 | F2: 53 | G2: 72 | H2: 85 | I2: Pays-de-la-Loire | J2: 2024 | K2: Objet Dataasso | L2: 44 | M2: 49 | N2: 53 | O2: 72 | P2: 85 | Q2: Pays-de-la-Loire | R2: Rappel : % asso actives | S2: Durée de vie moyenne | U2: Objet Dataasso | V2: 44 | W2: 49 | X2: 53 | Y2: 72 | Z2: 85 | AA2: Pays-de-la-Loire
C3: Autres et divers | D3: 17 | E3: 16 | F3: 7 | G3: 5 | H3: 19 | I3: =SUM(D3:H3) -> 64 | K3: Autres et divers | L3: =D3/D$11 -> 0.039812646 | M3: =E3/E$11 -> 0.065843621 | N3: =F3/F$11 -> 0.10294118 | O3: =G3/G$11 -> 0.030864198 | P3: =H3/H$11 -> 0.086363636 | Q3: =I3/I$11 -> 0.057142857 | R3: 0.065005097 | S3: 21 ans | U3: Autres et divers | V3: =D3/$I3 -> 0.265625 | W3: =E3/$I3 -> 0.25 | X3: =F3/$I3 -> 0.109375 | Y3: =G3/$I3 -> 0.078125 | Z3: =H3/$I3 -> 0.296875 | AA3: =I3/$I3 -> 1
C4: Culture | D4: 108 | E4: 51 | F4: 8 | G4: 29 | H4: 52 | I4: =SUM(D4:H4) -> 248 | K4: Culture | L4: =D4/D$11 -> 0.2529274 | M4: =E4/E$11 -> 0.20987654 | N4: =F4/F$11 -> 0.11764706 | O4: =G4/G$11 -> 0.17901235 | P4: =H4/H$11 -> 0.23636364 | Q4: =I4/I$11 -> 0.22142857 | R4: 0.17877116 | S4: 13 ans | U4: Culture | V4: =D4/$I4 -> 0.43548387 | W4: =E4/$I4 -> 0.20564516 | X4: =F4/$I4 -> 0.032258065 | Y4: =G4/$I4 -> 0.11693548 | Z4: =H4/$I4 -> 0.20967742 | AA4: =I4/$I4 -> 1
C5: Economie et développement local | D5: 28 | E5: 23 | F5: 5 | G5: 8 | H5: 12 | I5: =SUM(D5:H5) -> 76 | K5: Economie et développement local | L5: =D5/D$11 -> 0.06557377 | M5: =E5/E$11 -> 0.094650206 | N5: =F5/F$11 -> 0.073529412 | O5: =G5/G$11 -> 0.049382716 | P5: =H5/H$11 -> 0.054545455 | Q5: =I5/I$11 -> 0.067857143 | R5: 0.068482579 | S5: 15 ans | U5: Economie et développement local | V5: =D5/$I5 -> 0.36842105 | W5: =E5/$I5 -> 0.30263158 | X5: =F5/$I5 -> 0.065789474 | Y5: =G5/$I5 -> 0.10526316 | Z5: =H5/$I5 -> 0.15789474 | AA5: =I5/$I5 -> 1
C6: Education et formation | D6: 55 | E6: 14 | F6: 6 | G6: 8 | H6: 9 | I6: =SUM(D6:H6) -> 92 | K6: Education et formation | L6: =D6/D$11 -> 0.12880562 | M6: =E6/E$11 -> 0.057613169 | N6: =F6/F$11 -> 0.088235294 | O6: =G6/G$11 -> 0.049382716 | P6: =H6/H$11 -> 0.040909091 | Q6: =I6/I$11 -> 0.082142857 | R6: 0.082583055 | S6: 17 ans | U6: Education et formation | V6: =D6/$I6 -> 0.59782609 | W6: =E6/$I6 -> 0.15217391 | X6: =F6/$I6 -> 0.065217391 | Y6: =G6/$I6 -> 0.086956522 | Z6: =H6/$I6 -> 0.097826087 | AA6: =I6/$I6 -> 1
C7: Environnement et patrimoine | D7: 14 | E7: 11 | F7: 4 | G7: 11 | H7: 14 | I7: =SUM(D7:H7) -> 54 | K7: Environnement et patrimoine | L7: =D7/D$11 -> 0.032786885 | M7: =E7/E$11 -> 0.04526749 | N7: =F7/F$11 -> 0.058823529 | O7: =G7/G$11 -> 0.067901235 | P7: =H7/H$11 -> 0.063636364 | Q7: =I7/I$11 -> 0.048214286 | R7: 0.050990368 | S7: 12 ans | U7: Environnement et patrimoine | V7: =D7/$I7 -> 0.25925926 | W7: =E7/$I7 -> 0.2037037 | X7: =F7/$I7 -> 0.074074074 | Y7: =G7/$I7 -> 0.2037037 | Z7: =H7/$I7 -> 0.25925926 | AA7: =I7/$I7 -> 1
C8: Loisirs et vie sociale | D8: 83 | E8: 60 | F8: 14 | G8: 41 | H8: 43 | I8: =SUM(D8:H8) -> 241 | K8: Loisirs et vie sociale | L8: =D8/D$11 -> 0.19437939 | M8: =E8/E$11 -> 0.24691358 | N8: =F8/F$11 -> 0.20588235 | O8: =G8/G$11 -> 0.25308642 | P8: =H8/H$11 -> 0.19545455 | Q8: =I8/I$11 -> 0.21517857 | R8: 0.21690914 | S8: 18 ans | U8: Loisirs et vie sociale | V8: =D8/$I8 -> 0.34439834 | W8: =E8/$I8 -> 0.24896266 | X8: =F8/$I8 -> 0.058091286 | Y8: =G8/$I8 -> 0.17012448 | Z8: =H8/$I8 -> 0.17842324 | AA8: =I8/$I8 -> 1
C9: Santé et action sociale | D9: 71 | E9: 44 | F9: 15 | G9: 25 | H9: 31 | I9: =SUM(D9:H9) -> 186 | K9: Santé et action sociale | L9: =D9/D$11 -> 0.16627635 | M9: =E9/E$11 -> 0.18106996 | N9: =F9/F$11 -> 0.22058824 | O9: =G9/G$11 -> 0.15432099 | P9: =H9/H$11 -> 0.14090909 | Q9: =I9/I$11 -> 0.16607143 | R9: 0.1210259 | S9: 13 ans | U9: Santé et action sociale | V9: =D9/$I9 -> 0.38172043 | W9: =E9/$I9 -> 0.23655914 | X9: =F9/$I9 -> 0.080645161 | Y9: =G9/$I9 -> 0.1344086 | Z9: =H9/$I9 -> 0.16666667 | AA9: =I9/$I9 -> 1
C10: Sport | D10: 51 | E10: 24 | F10: 9 | G10: 35 | H10: 40 | I10: =SUM(D10:H10) -> 159 | K10: Sport | L10: =D10/D$11 -> 0.11943794 | M10: =E10/E$11 -> 0.098765432 | N10: =F10/F$11 -> 0.13235294 | O10: =G10/G$11 -> 0.21604938 | P10: =H10/H$11 -> 0.18181818 | Q10: =I10/I$11 -> 0.14196429 | R10: 0.2162327 | S10: 15 ans | U10: Sport | V10: =D10/$I10 -> 0.32075472 | W10: =E10/$I10 -> 0.1509434 | X10: =F10/$I10 -> 0.056603774 | Y10: =G10/$I10 -> 0.22012579 | Z10: =H10/$I10 -> 0.25157233 | AA10: =I10/$I10 -> 1
D11: =SUM(D3:D10) -> 427 | E11: =SUM(E3:E10) -> 243 | F11: =SUM(F3:F10) -> 68 | G11: =SUM(G3:G10) -> 162 | H11: =SUM(H3:H10) -> 220 | I11: =SUM(D11:H11) -> 1120 | L11: =D11/D$11 -> 1 | M11: =E11/E$11 -> 1 | N11: =F11/F$11 -> 1 | O11: =G11/G$11 -> 1 | P11: =H11/H$11 -> 1 | Q11: =I11/I$11 -> 1 | R11: 1 | S11: 15 ans | V11: =D11/$I11 -> 0.38125 | W11: =E11/$I11 -> 0.21696429 | X11: =F11/$I11 -> 0.060714286 | Y11: =G11/$I11 -> 0.14464286 | Z11: =H11/$I11 -> 0.19642857 | AA11: =I11/$I11 -> 1
B13: 2023 | C13: Objet Dataasso | D13: 44 | E13: 49 | F13: 53 | G13: 72 | H13: 85 | I13: Pays-de-la-Loire | J13: 2023 | K13: Objet Dataasso | L13: 44 | M13: 49 | N13: 53 | O13: 72 | P13: 85 | Q13: Pays-de-la-Loire | R13: Rappel : % asso actives | S13: Durée de vie moyenne | U13: Objet Dataasso | V13: 44 | W13: 49 | X13: 53 | Y13: 72 | Z13: 85 | AA13: Pays-de-la-Loire
C14: Autres et divers | D14: 23 | E14: 6 | F14: 4 | G14: 12 | H14: 13 | I14: =SUM(D14:H14) -> 58 | K14: Autres et divers | L14: =D14/D$22 -> 0.053488372 | M14: =E14/E$22 -> 0.025316456 | N14: =F14/F$22 -> 0.04 | O14: =G14/G$22 -> 0.06741573 | P14: =H14/H$22 -> 0.066666667 | Q14: =I14/I$22 -> 0.050877193 | R14: 0.06647677 | S14: 22 ans | U14: Autres et divers | V14: =D14/$I14 -> 0.39655172 | W14: =E14/$I14 -> 0.10344828 | X14: =F14/$I14 -> 0.068965517 | Y14: =G14/$I14 -> 0.20689655 | Z14: =H14/$I14 -> 0.22413793 | AA14: =I14/$I14 -> 1
C15: Culture | D15: 111 | E15: 46 | F15: 16 | G15: 36 | H15: 37 | I15: =SUM(D15:H15) -> 246 | K15: Culture | L15: =D15/D$22 -> 0.25813953 | M15: =E15/E$22 -> 0.19409283 | N15: =F15/F$22 -> 0.16 | O15: =G15/G$22 -> 0.20224719 | P15: =H15/H$22 -> 0.18974359 | Q15: =I15/I$22 -> 0.21578947 | R15: 0.17722228 | S15: 12 ans | U15: Culture | V15: =D15/$I15 -> 0.45121951 | W15: =E15/$I15 -> 0.18699187 | X15: =F15/$I15 -> 0.06504065 | Y15: =G15/$I15 -> 0.14634146 | Z15: =H15/$I15 -> 0.1504065 | AA15: =I15/$I15 -> 1
C16: Economie et développement local | D16: 35 | E16: 22 | F16: 5 | G16: 17 | H16: 16 | I16: =SUM(D16:H16) -> 95 | K16: Economie et développement local | L16: =D16/D$22 -> 0.081395349 | M16: =E16/E$22 -> 0.092827004 | N16: =F16/F$22 -> 0.05 | O16: =G16/G$22 -> 0.095505618 | P16: =H16/H$22 -> 0.082051282 | Q16: =I16/I$22 -> 0.083333333 | R16: 0.069590414 | S16: 19 ans | U16: Economie et développement local | V16: =D16/$I16 -> 0.36842105 | W16: =E16/$I16 -> 0.23157895 | X16: =F16/$I16 -> 0.052631579 | Y16: =G16/$I16 -> 0.17894737 | Z16: =H16/$I16 -> 0.16842105 | AA16: =I16/$I16 -> 1
C17: Education et formation | D17: 51 | E17: 16 | F17: 9 | G17: 5 | H17: 5 | I17: =SUM(D17:H17) -> 86 | K17: Education et formation | L17: =D17/D$22 -> 0.11860465 | M17: =E17/E$22 -> 0.067510549 | N17: =F17/F$22 -> 0.09 | O17: =G17/G$22 -> 0.028089888 | P17: =H17/H$22 -> 0.025641026 | Q17: =I17/I$22 -> 0.075438596 | R17: 0.083174541 | S17: 18 ans | U17: Education et formation | V17: =D17/$I17 -> 0.59302326 | W17: =E17/$I17 -> 0.18604651 | X17: =F17/$I17 -> 0.10465116 | Y17: =G17/$I17 -> 0.058139535 | Z17: =H17/$I17 -> 0.058139535 | AA17: =I17/$I17 -> 1
C18: Environnement et patrimoine | D18: 18 | E18: 10 | F18: 9 | G18: 6 | H18: 13 | I18: =SUM(D18:H18) -> 56 | K18: Environnement et patrimoine | L18: =D18/D$22 -> 0.041860465 | M18: =E18/E$22 -> 0.042194093 | N18: =F18/F$22 -> 0.09 | O18: =G18/G$22 -> 0.033707865 | P18: =H18/H$22 -> 0.066666667 | Q18: =I18/I$22 -> 0.049122807 | R18: 0.050289755 | S18: 12 ans | U18: Environnement et patrimoine | V18: =D18/$I18 -> 0.32142857 | W18: =E18/$I18 -> 0.17857143 | X18: =F18/$I18 -> 0.16071429 | Y18: =G18/$I18 -> 0.10714286 | Z18: =H18/$I18 -> 0.23214286 | AA18: =I18/$I18 -> 1
C19: Loisirs et vie sociale | D19: 81 | E19: 65 | F19: 20 | G19: 48 | H19: 45 | I19: =SUM(D19:H19) -> 259 | K19: Loisirs et vie sociale | L19: =D19/D$22 -> 0.18837209 | M19: =E19/E$22 -> 0.2742616 | N19: =F19/F$22 -> 0.2 | O19: =G19/G$22 -> 0.26966292 | P19: =H19/H$22 -> 0.23076923 | Q19: =I19/I$22 -> 0.22719298 | R19: 0.21703173 | S19: 19 ans | U19: Loisirs et vie sociale | V19: =D19/$I19 -> 0.31274131 | W19: =E19/$I19 -> 0.25096525 | X19: =F19/$I19 -> 0.077220077 | Y19: =G19/$I19 -> 0.18532819 | Z19: =H19/$I19 -> 0.17374517 | AA19: =I19/$I19 -> 1
C20: Santé et action sociale | D20: 60 | E20: 44 | F20: 21 | G20: 19 | H20: 41 | I20: =SUM(D20:H20) -> 185 | K20: Santé et action sociale | L20: =D20/D$22 -> 0.13953488 | M20: =E20/E$22 -> 0.18565401 | N20: =F20/F$22 -> 0.21 | O20: =G20/G$22 -> 0.10674157 | P20: =H20/H$22 -> 0.21025641 | Q20: =I20/I$22 -> 0.1622807 | R20: 0.11986052 | S20: 15 ans | U20: Santé et action sociale | V20: =D20/$I20 -> 0.32432432 | W20: =E20/$I20 -> 0.23783784 | X20: =F20/$I20 -> 0.11351351 | Y20: =G20/$I20 -> 0.1027027 | Z20: =H20/$I20 -> 0.22162162 | AA20: =I20/$I20 -> 1
C21: Sport | D21: 51 | E21: 28 | F21: 16 | G21: 35 | H21: 25 | I21: =SUM(D21:H21) -> 155 | K21: Sport | L21: =D21/D$22 -> 0.11860465 | M21: =E21/E$22 -> 0.11814346 | N21: =F21/F$22 -> 0.16 | O21: =G21/G$22 -> 0.19662921 | P21: =H21/H$22 -> 0.12820513 | Q21: =I21/I$22 -> 0.13596491 | R21: 0.21635399 | S21: 21 ans | U21: Sport | V21: =D21/$I21 -> 0.32903226 | W21: =E21/$I21 -> 0.18064516 | X21: =F21/$I21 -> 0.10322581 | Y21: =G21/$I21 -> 0.22580645 | Z21: =H21/$I21 -> 0.16129032 | AA21: =I21/$I21 -> 1
D22: 430 | E22: 237 | F22: 100 | G22: 178 | H22: 195 | I22: =SUM(D22:H22) -> 1140 | L22: =D22/D$22 -> 1 | M22: =E22/E$22 -> 1 | N22: =F22/F$22 -> 1 | O22: =G22/G$22 -> 1 | P22: =H22/H$22 -> 1 | Q22: =I22/I$22 -> 1 | R22: 1 | S22: 17 ans | V22: =D22/$I22 -> 0.37719298 | W22: =E22/$I22 -> 0.20789474 | X22: =F22/$I22 -> 0.087719298 | Y22: =G22/$I22 -> 0.15614035 | Z22: =H22/$I22 -> 0.17105263 | AA22: =I22/$I22 -> 1
B24: 2022 | C24: Objet Dataasso | D24: 44 | E24: 49 | F24: 53 | G24: 72 | H24: 85 | I24: Pays-de-la-Loire | J24: 2022 | K24: Objet Dataasso | L24: 44 | M24: 49 | N24: 53 | O24: 72 | P24: 85 | Q24: Pays-de-la-Loire | R24: Rappel : % asso actives | S24: Durée de vie moyenne | U24: Objet Dataasso | V24: 44 | W24: 49 | X24: 53 | Y24: 72 | Z24: 85 | AA24: Pays-de-la-Loire
C25: Autres et divers | D25: 20 | E25: 14 | F25: 4 | G25: 5 | H25: 16 | I25: =SUM(D25:H25) -> 59 | K25: Autres et divers | L25: =D25/D$33 -> 0.044742729 | M25: =E25/E$33 -> 0.054901961 | N25: =F25/F$33 -> 0.051948052 | O25: =G25/G$33 -> 0.027322404 | P25: =H25/H$33 -> 0.067226891 | Q25: =I25/I$33 -> 0.049166667 | R25: 0.068067634 | S25: 18 ans | U25: Autres et divers | V25: =D25/$I25 -> 0.33898305 | W25: =E25/$I25 -> 0.23728814 | X25: =F25/$I25 -> 0.06779661 | Y25: =G25/$I25 -> 0.084745763 | Z25: =H25/$I25 -> 0.27118644 | AA25: =I25/$I25 -> 1
C26: Culture | D26: 100 | E26: 58 | F26: 12 | G26: 34 | H26: 41 | I26: =SUM(D26:H26) -> 245 | K26: Culture | L26: =D26/D$33 -> 0.22371365 | M26: =E26/E$33 -> 0.22745098 | N26: =F26/F$33 -> 0.15584416 | O26: =G26/G$33 -> 0.18579235 | P26: =H26/H$33 -> 0.17226891 | Q26: =I26/I$33 -> 0.20416667 | R26: 0.17464641 | S26: 12 ans | U26: Culture | V26: =D26/$I26 -> 0.40816327 | W26: =E26/$I26 -> 0.23673469 | X26: =F26/$I26 -> 0.048979592 | Y26: =G26/$I26 -> 0.13877551 | Z26: =H26/$I26 -> 0.16734694 | AA26: =I26/$I26 -> 1
C27: Economie et développement local | D27: 34 | E27: 20 | F27: 8 | G27: 18 | H27: 27 | I27: =SUM(D27:H27) -> 107 | K27: Economie et développement local | L27: =D27/D$33 -> 0.07606264 | M27: =E27/E$33 -> 0.078431373 | N27: =F27/F$33 -> 0.1038961 | O27: =G27/G$33 -> 0.098360656 | P27: =H27/H$33 -> 0.11344538 | Q27: =I27/I$33 -> 0.089166667 | R27: 0.070636419 | S27: 17 ans | U27: Economie et développement local | V27: =D27/$I27 -> 0.31775701 | W27: =E27/$I27 -> 0.18691589 | X27: =F27/$I27 -> 0.074766355 | Y27: =G27/$I27 -> 0.1682243 | Z27: =H27/$I27 -> 0.25233645 | AA27: =I27/$I27 -> 1
C28: Education et formation | D28: 41 | E28: 21 | F28: 10 | G28: 6 | H28: 11 | I28: =SUM(D28:H28) -> 89 | K28: Education et formation | L28: =D28/D$33 -> 0.091722595 | M28: =E28/E$33 -> 0.082352941 | N28: =F28/F$33 -> 0.12987013 | O28: =G28/G$33 -> 0.032786885 | P28: =H28/H$33 -> 0.046218487 | Q28: =I28/I$33 -> 0.074166667 | R28: 0.084996853 | S28: 20 ans | U28: Education et formation | V28: =D28/$I28 -> 0.46067416 | W28: =E28/$I28 -> 0.23595506 | X28: =F28/$I28 -> 0.11235955 | Y28: =G28/$I28 -> 0.06741573 | Z28: =H28/$I28 -> 0.12359551 | AA28: =I28/$I28 -> 1
C29: Environnement et patrimoine | D29: 21 | E29: 10 | F29: 4 | G29: 8 | H29: 14 | I29: =SUM(D29:H29) -> 57 | K29: Environnement et patrimoine | L29: =D29/D$33 -> 0.046979866 | M29: =E29/E$33 -> 0.039215686 | N29: =F29/F$33 -> 0.051948052 | O29: =G29/G$33 -> 0.043715847 | P29: =H29/H$33 -> 0.058823529 | Q29: =I29/I$33 -> 0.0475 | R29: 0.048930705 | S29: 13 ans | U29: Environnement et patrimoine | V29: =D29/$I29 -> 0.36842105 | W29: =E29/$I29 -> 0.1754386 | X29: =F29/$I29 -> 0.070175439 | Y29: =G29/$I29 -> 0.14035088 | Z29: =H29/$I29 -> 0.24561404 | AA29: =I29/$I29 -> 1
C30: Loisirs et vie sociale | D30: 105 | E30: 67 | F30: 19 | G30: 49 | H30: 55 | I30: =SUM(D30:H30) -> 295 | K30: Loisirs et vie sociale | L30: =D30/D$33 -> 0.23489933 | M30: =E30/E$33 -> 0.2627451 | N30: =F30/F$33 -> 0.24675325 | O30: =G30/G$33 -> 0.26775956 | P30: =H30/H$33 -> 0.23109244 | Q30: =I30/I$33 -> 0.24583333 | R30: 0.21842922 | S30: 20 ans | U30: Loisirs et vie sociale | V30: =D30/$I30 -> 0.3559322 | W30: =E30/$I30 -> 0.22711864 | X30: =F30/$I30 -> 0.06440678 | Y30: =G30/$I30 -> 0.16610169 | Z30: =H30/$I30 -> 0.18644068 | AA30: =I30/$I30 -> 1
C31: Santé et action sociale | D31: 63 | E31: 44 | F31: 11 | G31: 26 | H31: 40 | I31: =SUM(D31:H31) -> 184 | K31: Santé et action sociale | L31: =D31/D$33 -> 0.1409396 | M31: =E31/E$33 -> 0.17254902 | N31: =F31/F$33 -> 0.14285714 | O31: =G31/G$33 -> 0.1420765 | P31: =H31/H$33 -> 0.16806723 | Q31: =I31/I$33 -> 0.15333333 | R31: 0.11733878 | S31: 18 ans | U31: Santé et action sociale | V31: =D31/$I31 -> 0.3423913 | W31: =E31/$I31 -> 0.23913043 | X31: =F31/$I31 -> 0.059782609 | Y31: =G31/$I31 -> 0.14130435 | Z31: =H31/$I31 -> 0.2173913 | AA31: =I31/$I31 -> 1
C32: Sport | D32: 63 | E32: 21 | F32: 9 | G32: 37 | H32: 34 | I32: =SUM(D32:H32) -> 164 | K32: Sport | L32: =D32/D$33 -> 0.1409396 | M32: =E32/E$33 -> 0.082352941 | N32: =F32/F$33 -> 0.11688312 | O32: =G32/G$33 -> 0.20218579 | P32: =H32/H$33 -> 0.14285714 | Q32: =I32/I$33 -> 0.13666667 | R32: 0.21695398 | S32: 21 ans | U32: Sport | V32: =D32/$I32 -> 0.38414634 | W32: =E32/$I32 -> 0.12804878 | X32: =F32/$I32 -> 0.054878049 | Y32: =G32/$I32 -> 0.22560976 | Z32: =H32/$I32 -> 0.20731707 | AA32: =I32/$I32 -> 1
C33: Total | D33: 447 | E33: 255 | F33: 77 | G33: 183 | H33: 238 | I33: =SUM(D33:H33) -> 1200 | L33: =D33/D$33 -> 1 | M33: =E33/E$33 -> 1 | N33: =F33/F$33 -> 1 | O33: =G33/G$33 -> 1 | P33: =H33/H$33 -> 1 | Q33: =I33/I$33 -> 1 | R33: 1 | S33: 17 ans | V33: =D33/$I33 -> 0.3725 | W33: =E33/$I33 -> 0.2125 | X33: =F33/$I33 -> 0.064166667 | Y33: =G33/$I33 -> 0.1525 | Z33: =H33/$I33 -> 0.19833333 | AA33: =I33/$I33 -> 1
B35: 2021 | C35: Objet Dataasso | D35: 44 | E35: 49 | F35: 53 | G35: 72 | H35: 85 | I35: Pays-de-la-Loire | J35: 2021 | K35: Objet Dataasso | L35: 44 | M35: 49 | N35: 53 | O35: 72 | P35: 85 | Q35: Pays-de-la-Loire | R35: Rappel : % asso actives | S35: Durée de vie moyenne | U35: Objet Dataasso | V35: 44 | W35: 49 | X35: 53 | Y35: 72 | Z35: 85 | AA35: Pays-de-la-Loire
C36: Autres et divers | D36: 22 | E36: 13 | F36: 2 | G36: 8 | H36: 11 | I36: =SUM(D36:H36) -> 56 | K36: Autres et divers | L36: =D36/D$44 -> 0.04845815 | M36: =E36/E$44 -> 0.04797048 | N36: =F36/F$44 -> 0.023255814 | O36: =G36/G$44 -> 0.049382716 | P36: =H36/H$44 -> 0.055276382 | Q36: =I36/I$44 -> 0.04778157 | R36: 0.068067634 | S36: 18 ans | U36: Autres et divers | V36: =D36/$I36 -> 0.39285714 | W36: =E36/$I36 -> 0.23214286 | X36: =F36/$I36 -> 0.035714286 | Y36: =G36/$I36 -> 0.14285714 | Z36: =H36/$I36 -> 0.19642857 | AA36: =I36/$I36 -> 1
C37: Culture | D37: 101 | E37: 50 | F37: 14 | G37: 19 | H37: 53 | I37: =SUM(D37:H37) -> 237 | K37: Culture | L37: =D37/D$44 -> 0.22246696 | M37: =E37/E$44 -> 0.18450185 | N37: =F37/F$44 -> 0.1627907 | O37: =G37/G$44 -> 0.11728395 | P37: =H37/H$44 -> 0.26633166 | Q37: =I37/I$44 -> 0.20221843 | R37: 0.17464641 | S37: 13 ans | U37: Culture | V37: =D37/$I37 -> 0.42616034 | W37: =E37/$I37 -> 0.21097046 | X37: =F37/$I37 -> 0.05907173 | Y37: =G37/$I37 -> 0.080168776 | Z37: =H37/$I37 -> 0.22362869 | AA37: =I37/$I37 -> 1
C38: Economie et développement local | D38: 32 | E38: 20 | F38: 9 | G38: 21 | H38: 15 | I38: =SUM(D38:H38) -> 97 | K38: Economie et développement local | L38: =D38/D$44 -> 0.070484581 | M38: =E38/E$44 -> 0.073800738 | N38: =F38/F$44 -> 0.10465116 | O38: =G38/G$44 -> 0.12962963 | P38: =H38/H$44 -> 0.075376884 | Q38: =I38/I$44 -> 0.082764505 | R38: 0.070636419 | S38: 18 ans | U38: Economie et développement local | V38: =D38/$I38 -> 0.32989691 | W38: =E38/$I38 -> 0.20618557 | X38: =F38/$I38 -> 0.092783505 | Y38: =G38/$I38 -> 0.21649485 | Z38: =H38/$I38 -> 0.15463918 | AA38: =I38/$I38 -> 1
C39: Education et formation | D39: 48 | E39: 15 | F39: 11 | G39: 8 | H39: 11 | I39: =SUM(D39:H39) -> 93 | K39: Education et formation | L39: =D39/D$44 -> 0.10572687 | M39: =E39/E$44 -> 0.055350554 | N39: =F39/F$44 -> 0.12790698 | O39: =G39/G$44 -> 0.049382716 | P39: =H39/H$44 -> 0.055276382 | Q39: =I39/I$44 -> 0.079351536 | R39: 0.084996853 | S39: 19 ans | U39: Education et formation | V39: =D39/$I39 -> 0.51612903 | W39: =E39/$I39 -> 0.16129032 | X39: =F39/$I39 -> 0.11827957 | Y39: =G39/$I39 -> 0.086021505 | Z39: =H39/$I39 -> 0.11827957 | AA39: =I39/$I39 -> 1
C40: Environnement et patrimoine | D40: 14 | E40: 22 | F40: 5 | G40: 11 | H40: 12 | I40: =SUM(D40:H40) -> 64 | K40: Environnement et patrimoine | L40: =D40/D$44 -> 0.030837004 | M40: =E40/E$44 -> 0.081180812 | N40: =F40/F$44 -> 0.058139535 | O40: =G40/G$44 -> 0.067901235 | P40: =H40/H$44 -> 0.060301508 | Q40: =I40/I$44 -> 0.054607509 | R40: 0.048930705 | S40: 11 ans | U40: Environnement et patrimoine | V40: =D40/$I40 -> 0.21875 | W40: =E40/$I40 -> 0.34375 | X40: =F40/$I40 -> 0.078125 | Y40: =G40/$I40 -> 0.171875 | Z40: =H40/$I40 -> 0.1875 | AA40: =I40/$I40 -> 1
C41: Loisirs et vie sociale | D41: 109 | E41: 48 | F41: 25 | G41: 50 | H41: 32 | I41: =SUM(D41:H41) -> 264 | K41: Loisirs et vie sociale | L41: =D41/D$44 -> 0.24008811 | M41: =E41/E$44 -> 0.17712177 | N41: =F41/F$44 -> 0.29069767 | O41: =G41/G$44 -> 0.30864198 | P41: =H41/H$44 -> 0.16080402 | Q41: =I41/I$44 -> 0.22525597 | R41: 0.21842922 | S41: 17 ans | U41: Loisirs et vie sociale | V41: =D41/$I41 -> 0.41287879 | W41: =E41/$I41 -> 0.18181818 | X41: =F41/$I41 -> 0.09469697 | Y41: =G41/$I41 -> 0.18939394 | Z41: =H41/$I41 -> 0.12121212 | AA41: =I41/$I41 -> 1
C42: Santé et action sociale | D42: 69 | E42: 55 | F42: 10 | G42: 29 | H42: 24 | I42: =SUM(D42:H42) -> 187 | K42: Santé et action sociale | L42: =D42/D$44 -> 0.15198238 | M42: =E42/E$44 -> 0.20295203 | N42: =F42/F$44 -> 0.11627907 | O42: =G42/G$44 -> 0.17901235 | P42: =H42/H$44 -> 0.12060302 | Q42: =I42/I$44 -> 0.15955631 | R42: 0.11733878 | S42: 18 ans | U42: Santé et action sociale | V42: =D42/$I42 -> 0.36898396 | W42: =E42/$I42 -> 0.29411765 | X42: =F42/$I42 -> 0.053475936 | Y42: =G42/$I42 -> 0.15508021 | Z42: =H42/$I42 -> 0.12834225 | AA42: =I42/$I42 -> 1
C43: Sport | D43: 59 | E43: 48 | F43: 10 | G43: 16 | H43: 41 | I43: =SUM(D43:H43) -> 174 | K43: Sport | L43: =D43/D$44 -> 0.12995595 | M43: =E43/E$44 -> 0.17712177 | N43: =F43/F$44 -> 0.11627907 | O43: =G43/G$44 -> 0.098765432 | P43: =H43/H$44 -> 0.20603015 | Q43: =I43/I$44 -> 0.14846416 | R43: 0.21695398 | S43: 21 ans | U43: Sport | V43: =D43/$I43 -> 0.33908046 | W43: =E43/$I43 -> 0.27586207 | X43: =F43/$I43 -> 0.057471264 | Y43: =G43/$I43 -> 0.091954023 | Z43: =H43/$I43 -> 0.23563218 | AA43: =I43/$I43 -> 1
...

Sheet Ann-2 - Asso par arrondissement
B2: DEP | C2: Arrondissement | D2: Nombre d'associations actives | J2: % 01/02/2025 | K2: Evolution 2019-2025 | M2: Nb d'associations pour 1000 hab
D3: 43497 | E3: 44105 | F3: 44228 | G3: 44593 | H3: 44958 | I3: 45689 | K3: Nombre | L3: %
B4: 44 | C4: Châteaubriant-Ancenis | D4: 4175 | E4: 4452 | F4: 4516 | G4: 4718 | H4: 4975 | I4: 5345 | J4: =H4/$H$7 -> 0.15332696 | K4: =I4-D4 -> 1170 | L4: =K4/D4 -> 0.28023952 | M4: 22.847543
B5: 44 | C5: Nantes | D5: 17598 | E5: 18563 | F5: 18835 | G5: 19898 | H5: 20842 | I5: 22158 | J5: =H5/$H$7 -> 0.64233982 | K5: =I5-D5 -> 4560 | L5: =K5/D5 -> 0.25912035 | M5: 24.928981
B6: 44 | C6: Saint-Nazaire | D6: 5418 | E6: 5832 | F6: 5903 | G6: 6287 | H6: 6630 | I6: 7055 | J6: =H6/$H$7 -> 0.20433322 | K6: =I6-D6 -> 1637 | L6: =K6/D6 -> 0.30214101 | M6: 20.135914
B7: Loire-Atlantique | D7: 27191 | E7: 28847 | F7: 29254 | G7: 30903 | H7: =SUM(H4:H6) -> 32447 | I7: =SUM(I4:I6) -> 34558 | J7: =H7/$H$7 -> 1 | K7: =I7-D7 -> 7367 | L7: =K7/D7 -> 0.27093524 | M7: ='Démographie des asso'!C6 -> 23.448297
B8: 49 | C8: Angers | D8: 14092 | E8: 14425 | F8: 14504 | G8: 14833 | H8: 15130 | I8: 15537 | J8: =H8/$H$12 -> 0.53694371 | K8: =I8-D8 -> 1445 | L8: =K8/D8 -> 0.10254045 | M8: 39.105386
B9: 49 | C9: Cholet | D9: 4212 | E9: 5704 | F9: 5904 | G9: 5962 | H9: 6143 | I9: 6402 | J9: =H9/$H$12 -> 0.21800696 | K9: =I9-D9 -> 2190 | L9: =K9/D9 -> 0.51994302 | M9: 28.192087
B10: 49 | C10: Saumur | D10: 2939 | E10: 4874 | F10: 4892 | G10: 4960 | H10: 5028 | I10: 5180 | J10: =H10/$H$12 -> 0.17843708 | K10: =I10-D10 -> 2241 | L10: =K10/D10 -> 0.76250425 | M10: 39.017776
B11: 49 | C11: Segré | D11: 1688 | E11: 1747 | F11: 1757 | G11: 1810 | H11: 1877 | I11: 1932 | J11: =H11/$H$12 -> 0.066612251 | K11: =I11-D11 -> 244 | L11: =K11/D11 -> 0.14454976 | M11: 27.213184
B12: Maine-et-Loire | D12: 22931 | E12: 26750 | F12: 27057 | G12: 27565 | H12: =SUM(H8:H11) -> 28178 | I12: =SUM(I8:I11) -> 29051 | J12: =H12/$H$12 -> 1 | K12: =I12-D12 -> 6120 | L12: =K12/D12 -> 0.26688762 | M12: ='Démographie des asso'!D6 -> 35.097464
B13: 53 | C13: Château-Gontier | D13: 2157 | E13: 2198 | F13: 2213 | G13: 2262 | H13: 2320 | I13: 2366 | J13: =H13/$H$16 -> 0.28906055 | K13: =I13-D13 -> 209 | L13: =K13/D13 -> 0.096893834 | M13: 32.376365
B14: 53 | C14: Laval | D14: 2350 | E14: 2474 | F14: 2493 | G14: 2577 | H14: 2691 | I14: 2843 | J14: =H14/$H$16 -> 0.33528532 | K14: =I14-D14 -> 493 | L14: =K14/D14 -> 0.20978723 | M14: 24.749286
B15: 53 | C15: Mayenne | D15: 2697 | E15: 2777 | F15: 2799 | G15: 2916 | H15: 3015 | I15: 3119 | J15: =H15/$H$16 -> 0.37565412 | K15: =I15-D15 -> 422 | L15: =K15/D15 -> 0.15647015 | M15: 26.572724
B16: Mayenne | D16: 7204 | E16: 7449 | F16: 7505 | G16: 7755 | H16: =SUM(H13:H15) -> 8026 | I16: =SUM(I13:I15) -> 8328 | J16: =H16/$H$16 -> 1 | K16: =I16-D16 -> 1124 | L16: =K16/D16 -> 0.15602443 | M16: ='Démographie des asso'!E6 -> 27.265852
B17: 72 | C17: La Flèche | D17: 4420 | E17: 4520 | F17: 4533 | G17: 4655 | H17: 4782 | I17: 4934 | J17: =H17/$H$20 -> 0.26668897 | K17: =I17-D17 -> 514 | L17: =K17/D17 -> 0.11628959 | M17: 33.200102
B18: 72 | C18: Le Mans | D18: 8270 | E18: 8418 | F18: 8429 | G18: 8669 | H18: 8858 | I18: 9167 | J18: =H18/$H$20 -> 0.4940048 | K18: =I18-D18 -> 897 | L18: =K18/D18 -> 0.10846433 | M18: 34.202927
B19: 72 | C19: Mamers | D19: 3965 | E19: 4053 | F19: 4067 | G19: 4181 | H19: 4291 | I19: 4399 | J19: =H19/$H$20 -> 0.23930623 | K19: =I19-D19 -> 434 | L19: =K19/D19 -> 0.10945776 | M19: 29.437351
B20: Sarthe | D20: 16655 | E20: 16991 | F20: 17029 | G20: 17505 | H20: =SUM(H17:H19) -> 17931 | I20: =SUM(I17:I19) -> 18500 | J20: =H20/$H$20 -> 1 | K20: =I20-D20 -> 1845 | L20: =K20/D20 -> 0.11077754 | M20: ='Démographie des asso'!F6 -> 32.678065
B21: 85 | C21: Fontenay-le-Comte | D21: 2844 | E21: 2922 | F21: 2946 | G21: 3101 | H21: 3231 | I21: 3375 | J21: =H21/$H$24 -> 0.19058574 | K21: =I21-D21 -> 531 | L21: =K21/D21 -> 0.18670886 | M21: 23.554454
B22: 85 | C22: La Roche-sur-Yon | D22: 8043 | E22: 8368 | F22: 8424 | G22: 8611 | H22: 8893 | I22: 9282 | J22: =H22/$H$24 -> 0.52456792 | K22: =I22-D22 -> 1239 | L22: =K22/D22 -> 0.154047 | M22: 30.530786
B23: 85 | C23: Les Sables-d'Olonne | D23: 4126 | E23: 4326 | F23: 4368 | G23: 4579 | H23: 4829 | I23: 5224 | J23: =H23/$H$24 -> 0.28484634 | K23: =I23-D23 -> 1098 | L23: =K23/D23 -> 0.2661173 | M23: 20.371634
B24: Vendée | D24: 15013 | E24: 15616 | F24: 15738 | G24: 16291 | H24: =SUM(H21:H23) -> 16953 | I24: =SUM(I21:I23) -> 17881 | J24: =H24/$H$24 -> 1 | K24: =I24-D24 -> 2868 | L24: =K24/D24 -> 0.19103444 | M24: ='Démographie des asso'!G6 -> 25.314897
B26: Pays de la Loire | D26: 88994 | E26: 95653 | F26: 96583 | G26: 100019 | H26: =H7+H12+H16+H20+H24 -> 103535 | I26: =I7+I12+I16+I20+I24 -> 108318 | K26: =I26-D26 -> 19324 | L26: =K26/D26 -> 0.21713823 | M26: ='Démographie des asso'!H6 -> 27.922652
M27: Source : DATAGOUV – Fichier RNA_waldec 01/02/2019, 01/02/2020, 01/10/2021, 01/02/2022, 01/02/2023 et 01/02/2025; RP-Insee 2022

Sheet Ann-3 - Créations 2019-2022
C2: Nombre de créations d'association par mois | K2: Evolution 2019-2024
C3: Mois | D3: 44 | E3: 49 | F3: 53 | G3: 72 | H3: 85 | I3: PDL | K3: Mois | L3: 44 | M3: 49 | N3: 53 | O3: 72 | P3: 85 | Q3: PDL
B4: 2024 | C4: Janvier | D4: 169 | E4: 78 | F4: 26 | G4: 54 | H4: 58 | I4: =SUM(D4:H4) -> 385 | K4: Janvier | L4: =D4-D20 -> -10 | M4: =E4-E20 -> -3 | N4: =F4-F20 -> -7 | O4: =G4-G20 -> 4 | P4: =H4-H20 -> -11 | Q4: =I4-I20 -> -27
C5: Février | D5: 142 | E5: 90 | F5: 33 | G5: 46 | H5: 75 | I5: =SUM(D5:H5) -> 386 | K5: Février | L5: =D5-D21 -> -17 | M5: =E5-E21 -> 25 | N5: =F5-F21 -> 15 | O5: =G5-G21 -> 1 | P5: =H5-H21 -> 13 | Q5: =I5-I21 -> 37
